[2023-09-28T18:58:55.683+0000] {taskinstance.py:1165} INFO - Dependencies all met for <TaskInstance: user_processing.is_api_available scheduled__2023-09-27T00:00:00+00:00 [queued]>
[2023-09-28T18:58:55.739+0000] {taskinstance.py:1165} INFO - Dependencies all met for <TaskInstance: user_processing.is_api_available scheduled__2023-09-27T00:00:00+00:00 [queued]>
[2023-09-28T18:58:55.741+0000] {taskinstance.py:1362} INFO - 
--------------------------------------------------------------------------------
[2023-09-28T18:58:55.744+0000] {taskinstance.py:1363} INFO - Starting attempt 1 of 1
[2023-09-28T18:58:55.747+0000] {taskinstance.py:1364} INFO - 
--------------------------------------------------------------------------------
[2023-09-28T18:58:55.808+0000] {taskinstance.py:1383} INFO - Executing <Task(HttpSensor): is_api_available> on 2023-09-27 00:00:00+00:00
[2023-09-28T18:58:55.829+0000] {standard_task_runner.py:55} INFO - Started process 3912 to run task
[2023-09-28T18:58:55.843+0000] {standard_task_runner.py:82} INFO - Running: ['***', 'tasks', 'run', 'user_processing', 'is_api_available', 'scheduled__2023-09-27T00:00:00+00:00', '--job-id', '14', '--raw', '--subdir', 'DAGS_FOLDER/user_processing.py', '--cfg-path', '/tmp/tmp4x18u4ca']
[2023-09-28T18:58:55.850+0000] {standard_task_runner.py:83} INFO - Job 14: Subtask is_api_available
[2023-09-28T18:58:56.095+0000] {task_command.py:376} INFO - Running <TaskInstance: user_processing.is_api_available scheduled__2023-09-27T00:00:00+00:00 [running]> on host d9ce0052adca
[2023-09-28T18:58:56.345+0000] {taskinstance.py:1592} INFO - Exporting the following env vars:
AIRFLOW_CTX_DAG_OWNER=***
AIRFLOW_CTX_DAG_ID=user_processing
AIRFLOW_CTX_TASK_ID=is_api_available
AIRFLOW_CTX_EXECUTION_DATE=2023-09-27T00:00:00+00:00
AIRFLOW_CTX_TRY_NUMBER=1
AIRFLOW_CTX_DAG_RUN_ID=scheduled__2023-09-27T00:00:00+00:00
[2023-09-28T18:58:56.349+0000] {http.py:120} INFO - Poking: api/
[2023-09-28T18:58:56.432+0000] {taskinstance.py:1851} ERROR - Task failed with exception
Traceback (most recent call last):
  File "/home/airflow/.local/lib/python3.7/site-packages/airflow/sensors/base.py", line 189, in execute
    poke_return = self.poke(context)
  File "/home/airflow/.local/lib/python3.7/site-packages/airflow/providers/http/sensors/http.py", line 135, in poke
    raise exc
  File "/home/airflow/.local/lib/python3.7/site-packages/airflow/providers/http/sensors/http.py", line 126, in poke
    extra_options=self.extra_options,
  File "/home/airflow/.local/lib/python3.7/site-packages/airflow/providers/http/hooks/http.py", line 128, in run
    session = self.get_conn(headers)
  File "/home/airflow/.local/lib/python3.7/site-packages/airflow/providers/http/hooks/http.py", line 82, in get_conn
    conn = self.get_connection(self.http_conn_id)
  File "/home/airflow/.local/lib/python3.7/site-packages/airflow/hooks/base.py", line 70, in get_connection
    conn = Connection.get_connection_from_secrets(conn_id)
  File "/home/airflow/.local/lib/python3.7/site-packages/airflow/models/connection.py", line 432, in get_connection_from_secrets
    raise AirflowNotFoundException(f"The conn_id `{conn_id}` isn't defined")
airflow.exceptions.AirflowNotFoundException: The conn_id `user_api` isn't defined
[2023-09-28T18:58:56.454+0000] {taskinstance.py:1406} INFO - Marking task as FAILED. dag_id=user_processing, task_id=is_api_available, execution_date=20230927T000000, start_date=20230928T185855, end_date=20230928T185856
[2023-09-28T18:58:56.477+0000] {standard_task_runner.py:105} ERROR - Failed to execute job 14 for task is_api_available (The conn_id `user_api` isn't defined; 3912)
[2023-09-28T18:58:56.551+0000] {local_task_job.py:164} INFO - Task exited with return code 1
[2023-09-28T18:58:56.598+0000] {local_task_job.py:273} INFO - 0 downstream tasks scheduled from follow-on schedule check
