[2023-09-28T18:58:53.467+0000] {taskinstance.py:1165} INFO - Dependencies all met for <TaskInstance: user_processing.extract_user manual__2023-09-28T18:58:47.451100+00:00 [queued]>
[2023-09-28T18:58:53.532+0000] {taskinstance.py:1165} INFO - Dependencies all met for <TaskInstance: user_processing.extract_user manual__2023-09-28T18:58:47.451100+00:00 [queued]>
[2023-09-28T18:58:53.535+0000] {taskinstance.py:1362} INFO - 
--------------------------------------------------------------------------------
[2023-09-28T18:58:53.537+0000] {taskinstance.py:1363} INFO - Starting attempt 1 of 1
[2023-09-28T18:58:53.540+0000] {taskinstance.py:1364} INFO - 
--------------------------------------------------------------------------------
[2023-09-28T18:58:53.635+0000] {taskinstance.py:1383} INFO - Executing <Task(SimpleHttpOperator): extract_user> on 2023-09-28 18:58:47.451100+00:00
[2023-09-28T18:58:53.667+0000] {standard_task_runner.py:55} INFO - Started process 3903 to run task
[2023-09-28T18:58:53.688+0000] {standard_task_runner.py:82} INFO - Running: ['***', 'tasks', 'run', 'user_processing', 'extract_user', 'manual__2023-09-28T18:58:47.451100+00:00', '--job-id', '12', '--raw', '--subdir', 'DAGS_FOLDER/user_processing.py', '--cfg-path', '/tmp/tmpna07f146']
[2023-09-28T18:58:53.696+0000] {standard_task_runner.py:83} INFO - Job 12: Subtask extract_user
[2023-09-28T18:58:54.065+0000] {task_command.py:376} INFO - Running <TaskInstance: user_processing.extract_user manual__2023-09-28T18:58:47.451100+00:00 [running]> on host d9ce0052adca
[2023-09-28T18:58:54.479+0000] {taskinstance.py:1592} INFO - Exporting the following env vars:
AIRFLOW_CTX_DAG_OWNER=***
AIRFLOW_CTX_DAG_ID=user_processing
AIRFLOW_CTX_TASK_ID=extract_user
AIRFLOW_CTX_EXECUTION_DATE=2023-09-28T18:58:47.451100+00:00
AIRFLOW_CTX_TRY_NUMBER=1
AIRFLOW_CTX_DAG_RUN_ID=manual__2023-09-28T18:58:47.451100+00:00
[2023-09-28T18:58:54.486+0000] {http.py:121} INFO - Calling HTTP method
[2023-09-28T18:58:54.648+0000] {taskinstance.py:1851} ERROR - Task failed with exception
Traceback (most recent call last):
  File "/home/airflow/.local/lib/python3.7/site-packages/airflow/providers/http/operators/http.py", line 123, in execute
    response = http.run(self.endpoint, self.data, self.headers, self.extra_options)
  File "/home/airflow/.local/lib/python3.7/site-packages/airflow/providers/http/hooks/http.py", line 128, in run
    session = self.get_conn(headers)
  File "/home/airflow/.local/lib/python3.7/site-packages/airflow/providers/http/hooks/http.py", line 82, in get_conn
    conn = self.get_connection(self.http_conn_id)
  File "/home/airflow/.local/lib/python3.7/site-packages/airflow/hooks/base.py", line 70, in get_connection
    conn = Connection.get_connection_from_secrets(conn_id)
  File "/home/airflow/.local/lib/python3.7/site-packages/airflow/models/connection.py", line 432, in get_connection_from_secrets
    raise AirflowNotFoundException(f"The conn_id `{conn_id}` isn't defined")
airflow.exceptions.AirflowNotFoundException: The conn_id `user_api` isn't defined
[2023-09-28T18:58:54.684+0000] {taskinstance.py:1406} INFO - Marking task as FAILED. dag_id=user_processing, task_id=extract_user, execution_date=20230928T185847, start_date=20230928T185853, end_date=20230928T185854
[2023-09-28T18:58:54.748+0000] {standard_task_runner.py:105} ERROR - Failed to execute job 12 for task extract_user (The conn_id `user_api` isn't defined; 3903)
[2023-09-28T18:58:54.817+0000] {local_task_job.py:164} INFO - Task exited with return code 1
[2023-09-28T18:58:54.954+0000] {local_task_job.py:273} INFO - 0 downstream tasks scheduled from follow-on schedule check
