[2023-10-05T20:08:39.711+0000] {taskinstance.py:1165} INFO - Dependencies all met for <TaskInstance: user_processing.store_user manual__2023-10-05T20:08:32.531109+00:00 [queued]>
[2023-10-05T20:08:39.724+0000] {taskinstance.py:1165} INFO - Dependencies all met for <TaskInstance: user_processing.store_user manual__2023-10-05T20:08:32.531109+00:00 [queued]>
[2023-10-05T20:08:39.725+0000] {taskinstance.py:1362} INFO - 
--------------------------------------------------------------------------------
[2023-10-05T20:08:39.725+0000] {taskinstance.py:1363} INFO - Starting attempt 1 of 1
[2023-10-05T20:08:39.726+0000] {taskinstance.py:1364} INFO - 
--------------------------------------------------------------------------------
[2023-10-05T20:08:39.740+0000] {taskinstance.py:1383} INFO - Executing <Task(PythonOperator): store_user> on 2023-10-05 20:08:32.531109+00:00
[2023-10-05T20:08:39.747+0000] {standard_task_runner.py:55} INFO - Started process 1525 to run task
[2023-10-05T20:08:39.752+0000] {standard_task_runner.py:82} INFO - Running: ['***', 'tasks', 'run', 'user_processing', 'store_user', 'manual__2023-10-05T20:08:32.531109+00:00', '--job-id', '39', '--raw', '--subdir', 'DAGS_FOLDER/user_processing.py', '--cfg-path', '/tmp/tmp25nb4cuf']
[2023-10-05T20:08:39.759+0000] {standard_task_runner.py:83} INFO - Job 39: Subtask store_user
[2023-10-05T20:08:39.892+0000] {task_command.py:376} INFO - Running <TaskInstance: user_processing.store_user manual__2023-10-05T20:08:32.531109+00:00 [running]> on host ca408aed2033
[2023-10-05T20:08:39.985+0000] {taskinstance.py:1592} INFO - Exporting the following env vars:
AIRFLOW_CTX_DAG_OWNER=***
AIRFLOW_CTX_DAG_ID=user_processing
AIRFLOW_CTX_TASK_ID=store_user
AIRFLOW_CTX_EXECUTION_DATE=2023-10-05T20:08:32.531109+00:00
AIRFLOW_CTX_TRY_NUMBER=1
AIRFLOW_CTX_DAG_RUN_ID=manual__2023-10-05T20:08:32.531109+00:00
[2023-10-05T20:08:39.987+0000] {postgres.py:129} INFO - Running copy expert: COPY users FROM stdin WITH DELIMITER as ',' , filename: /tmp/processed_user.csv
[2023-10-05T20:08:40.015+0000] {taskinstance.py:1851} ERROR - Task failed with exception
Traceback (most recent call last):
  File "/home/airflow/.local/lib/python3.7/site-packages/airflow/operators/python.py", line 175, in execute
    return_value = self.execute_callable()
  File "/home/airflow/.local/lib/python3.7/site-packages/airflow/operators/python.py", line 193, in execute_callable
    return self.python_callable(*self.op_args, **self.op_kwargs)
  File "/opt/airflow/dags/user_processing.py", line 28, in _store_users
    filename= '/tmp/processed_user.csv'
  File "/home/airflow/.local/lib/python3.7/site-packages/airflow/providers/postgres/hooks/postgres.py", line 135, in copy_expert
    with closing(self.get_conn()) as conn:
  File "/home/airflow/.local/lib/python3.7/site-packages/airflow/providers/postgres/hooks/postgres.py", line 88, in get_conn
    conn = deepcopy(self.connection or self.get_connection(conn_id))
  File "/home/airflow/.local/lib/python3.7/site-packages/airflow/hooks/base.py", line 70, in get_connection
    conn = Connection.get_connection_from_secrets(conn_id)
  File "/home/airflow/.local/lib/python3.7/site-packages/airflow/models/connection.py", line 432, in get_connection_from_secrets
    raise AirflowNotFoundException(f"The conn_id `{conn_id}` isn't defined")
airflow.exceptions.AirflowNotFoundException: The conn_id `postgres_default` isn't defined
[2023-10-05T20:08:40.024+0000] {taskinstance.py:1406} INFO - Marking task as FAILED. dag_id=user_processing, task_id=store_user, execution_date=20231005T200832, start_date=20231005T200839, end_date=20231005T200840
[2023-10-05T20:08:40.038+0000] {standard_task_runner.py:105} ERROR - Failed to execute job 39 for task store_user (The conn_id `postgres_default` isn't defined; 1525)
[2023-10-05T20:08:40.086+0000] {local_task_job.py:164} INFO - Task exited with return code 1
[2023-10-05T20:08:40.126+0000] {local_task_job.py:273} INFO - 0 downstream tasks scheduled from follow-on schedule check
