[2023-10-10T17:54:50.803+0000] {taskinstance.py:1103} INFO - Dependencies all met for dep_context=non-requeueable deps ti=<TaskInstance: group_dag.dimension_layer.insert_into_dim_genre manual__2023-10-10T17:54:36.006761+00:00 [queued]>
[2023-10-10T17:54:50.837+0000] {taskinstance.py:1103} INFO - Dependencies all met for dep_context=requeueable deps ti=<TaskInstance: group_dag.dimension_layer.insert_into_dim_genre manual__2023-10-10T17:54:36.006761+00:00 [queued]>
[2023-10-10T17:54:50.839+0000] {taskinstance.py:1308} INFO - Starting attempt 1 of 1
[2023-10-10T17:54:50.926+0000] {taskinstance.py:1327} INFO - Executing <Task(MsSqlOperator): dimension_layer.insert_into_dim_genre> on 2023-10-10 17:54:36.006761+00:00
[2023-10-10T17:54:51.053+0000] {standard_task_runner.py:84} INFO - Running: ['***', 'tasks', 'run', 'group_dag', 'dimension_layer.insert_into_dim_genre', 'manual__2023-10-10T17:54:36.006761+00:00', '--job-id', '151', '--raw', '--subdir', 'DAGS_FOLDER/group_dag.py', '--cfg-path', '/tmp/tmp_cz9p2ar']
[2023-10-10T17:54:51.059+0000] {standard_task_runner.py:85} INFO - Job 151: Subtask dimension_layer.insert_into_dim_genre
[2023-10-10T17:54:51.011+0000] {standard_task_runner.py:57} INFO - Started process 991 to run task
[2023-10-10T17:54:51.239+0000] {task_command.py:410} INFO - Running <TaskInstance: group_dag.dimension_layer.insert_into_dim_genre manual__2023-10-10T17:54:36.006761+00:00 [running]> on host 2c73f027d5a5
[2023-10-10T17:54:51.618+0000] {taskinstance.py:1547} INFO - Exporting env vars: AIRFLOW_CTX_DAG_OWNER='***' AIRFLOW_CTX_DAG_ID='group_dag' AIRFLOW_CTX_TASK_ID='dimension_layer.insert_into_dim_genre' AIRFLOW_CTX_EXECUTION_DATE='2023-10-10T17:54:36.006761+00:00' AIRFLOW_CTX_TRY_NUMBER='1' AIRFLOW_CTX_DAG_RUN_ID='manual__2023-10-10T17:54:36.006761+00:00'
[2023-10-10T17:54:51.660+0000] {sql.py:265} INFO - Executing:       
            INSERT INTO dim_genre (genre_id, genre)
            SELECT s.genre_id, s.genre FROM stg_genre s
            WHERE NOT EXISTS (SELECT 1 FROM dim_genre d WHERE d.genre_id = s.genre_id)
            
[2023-10-10T17:54:51.705+0000] {base.py:73} INFO - Using connection ID 'sqlserver' for task execution.
[2023-10-10T17:54:52.004+0000] {base.py:73} INFO - Using connection ID 'sqlserver' for task execution.
[2023-10-10T17:54:53.137+0000] {sql.py:375} INFO - Running statement:       
            INSERT INTO dim_genre (genre_id, genre)
            SELECT s.genre_id, s.genre FROM stg_genre s
            WHERE NOT EXISTS (SELECT 1 FROM dim_genre d WHERE d.genre_id = s.genre_id)
            , parameters: None
[2023-10-10T17:54:53.226+0000] {taskinstance.py:1824} ERROR - Task failed with exception
Traceback (most recent call last):
  File "src/pymssql/_pymssql.pyx", line 459, in pymssql._pymssql.Cursor.execute
  File "src/pymssql/_mssql.pyx", line 1087, in pymssql._mssql.MSSQLConnection.execute_query
  File "src/pymssql/_mssql.pyx", line 1118, in pymssql._mssql.MSSQLConnection.execute_query
  File "src/pymssql/_mssql.pyx", line 1251, in pymssql._mssql.MSSQLConnection.format_and_run_query
  File "src/pymssql/_mssql.pyx", line 1789, in pymssql._mssql.check_cancel_and_raise
  File "src/pymssql/_mssql.pyx", line 1835, in pymssql._mssql.raise_MSSQLDatabaseException
pymssql._mssql.MSSQLDatabaseException: (208, b"Invalid object name 'dim_genre'.DB-Lib error message 20018, severity 16:\nGeneral SQL Server error: Check messages from the SQL Server\n")

During handling of the above exception, another exception occurred:

Traceback (most recent call last):
  File "/home/airflow/.local/lib/python3.7/site-packages/airflow/providers/common/sql/operators/sql.py", line 277, in execute
    **extra_kwargs,
  File "/home/airflow/.local/lib/python3.7/site-packages/airflow/providers/common/sql/hooks/sql.py", line 349, in run
    self._run_command(cur, sql_statement, parameters)
  File "/home/airflow/.local/lib/python3.7/site-packages/airflow/providers/common/sql/hooks/sql.py", line 380, in _run_command
    cur.execute(sql_statement)
  File "src/pymssql/_pymssql.pyx", line 476, in pymssql._pymssql.Cursor.execute
pymssql._pymssql.ProgrammingError: (208, b"Invalid object name 'dim_genre'.DB-Lib error message 20018, severity 16:\nGeneral SQL Server error: Check messages from the SQL Server\n")
[2023-10-10T17:54:53.261+0000] {taskinstance.py:1350} INFO - Marking task as FAILED. dag_id=group_dag, task_id=dimension_layer.insert_into_dim_genre, execution_date=20231010T175436, start_date=20231010T175450, end_date=20231010T175453
[2023-10-10T17:54:53.364+0000] {standard_task_runner.py:109} ERROR - Failed to execute job 151 for task dimension_layer.insert_into_dim_genre ((208, b"Invalid object name 'dim_genre'.DB-Lib error message 20018, severity 16:\nGeneral SQL Server error: Check messages from the SQL Server\n"); 991)
[2023-10-10T17:54:53.417+0000] {local_task_job_runner.py:225} INFO - Task exited with return code 1
[2023-10-10T17:54:53.520+0000] {taskinstance.py:2653} INFO - 0 downstream tasks scheduled from follow-on schedule check
